Watching for file changes with StatReloader
"OPTIONS /graphql/ HTTP/1.1" 200 0
"OPTIONS /graphql/ HTTP/1.1" 200 0
"OPTIONS /graphql/ HTTP/1.1" 200 0
Not Found: /favicon.ico
Not Found: /manifest.json
"GET /favicon.ico HTTP/1.1" 404 2582
"GET /manifest.json HTTP/1.1" 404 2588
Internal Server Error: /graphql/
Traceback (most recent call last):
  File "/usr/local/lib/python3.11/site-packages/graphene_django/settings.py", line 80, in import_from_string
    module = importlib.import_module(module_path)
             ^^^^^^^^^^^^^^^^^^^^^^^^^^^^^^^^^^^^
  File "/usr/local/lib/python3.11/importlib/__init__.py", line 126, in import_module
    return _bootstrap._gcd_import(name[level:], package, level)
           ^^^^^^^^^^^^^^^^^^^^^^^^^^^^^^^^^^^^^^^^^^^^^^^^^^^^
  File "<frozen importlib._bootstrap>", line 1204, in _gcd_import
  File "<frozen importlib._bootstrap>", line 1176, in _find_and_load
  File "<frozen importlib._bootstrap>", line 1147, in _find_and_load_unlocked
  File "<frozen importlib._bootstrap>", line 690, in _load_unlocked
  File "<frozen importlib._bootstrap_external>", line 940, in exec_module
  File "<frozen importlib._bootstrap>", line 241, in _call_with_frames_removed
  File "/app/starwars/schema.py", line 4, in <module>
    from graphene_django.filter import DjangoFilterConnectionField
ImportError: cannot import name 'DjangoFilterConnectionField' from 'graphene_django.filter' (/usr/local/lib/python3.11/site-packages/graphene_django/filter/__init__.py)

During handling of the above exception, another exception occurred:

Traceback (most recent call last):
  File "/usr/local/lib/python3.11/site-packages/django/core/handlers/exception.py", line 55, in inner
    response = get_response(request)
               ^^^^^^^^^^^^^^^^^^^^^
  File "/usr/local/lib/python3.11/site-packages/django/core/handlers/base.py", line 197, in _get_response
    response = wrapped_callback(request, *callback_args, **callback_kwargs)
               ^^^^^^^^^^^^^^^^^^^^^^^^^^^^^^^^^^^^^^^^^^^^^^^^^^^^^^^^^^^^
  File "/usr/local/lib/python3.11/site-packages/django/views/decorators/csrf.py", line 56, in wrapper_view
    return view_func(*args, **kwargs)
           ^^^^^^^^^^^^^^^^^^^^^^^^^^
  File "/usr/local/lib/python3.11/site-packages/django/views/generic/base.py", line 97, in view
    self = cls(**initkwargs)
           ^^^^^^^^^^^^^^^^^
  File "/usr/local/lib/python3.11/site-packages/graphene_django/views.py", line 114, in __init__
    schema = graphene_settings.SCHEMA
             ^^^^^^^^^^^^^^^^^^^^^^^^
  File "/usr/local/lib/python3.11/site-packages/graphene_django/settings.py", line 127, in __getattr__
    val = perform_import(val, attr)
          ^^^^^^^^^^^^^^^^^^^^^^^^^
  File "/usr/local/lib/python3.11/site-packages/graphene_django/settings.py", line 66, in perform_import
    return import_from_string(val, setting_name)
           ^^^^^^^^^^^^^^^^^^^^^^^^^^^^^^^^^^^^^
  File "/usr/local/lib/python3.11/site-packages/graphene_django/settings.py", line 89, in import_from_string
    raise ImportError(msg)
ImportError: Could not import 'starwars.schema.schema' for Graphene setting 'SCHEMA'. ImportError: cannot import name 'DjangoFilterConnectionField' from 'graphene_django.filter' (/usr/local/lib/python3.11/site-packages/graphene_django/filter/__init__.py).
Internal Server Error: /graphql/
Traceback (most recent call last):
  File "/usr/local/lib/python3.11/site-packages/graphene_django/settings.py", line 80, in import_from_string
    module = importlib.import_module(module_path)
             ^^^^^^^^^^^^^^^^^^^^^^^^^^^^^^^^^^^^
  File "/usr/local/lib/python3.11/importlib/__init__.py", line 126, in import_module
    return _bootstrap._gcd_import(name[level:], package, level)
           ^^^^^^^^^^^^^^^^^^^^^^^^^^^^^^^^^^^^^^^^^^^^^^^^^^^^
  File "<frozen importlib._bootstrap>", line 1204, in _gcd_import
  File "<frozen importlib._bootstrap>", line 1176, in _find_and_load
  File "<frozen importlib._bootstrap>", line 1147, in _find_and_load_unlocked
  File "<frozen importlib._bootstrap>", line 690, in _load_unlocked
  File "<frozen importlib._bootstrap_external>", line 940, in exec_module
  File "<frozen importlib._bootstrap>", line 241, in _call_with_frames_removed
  File "/app/starwars/schema.py", line 4, in <module>
    from graphene_django.filter import DjangoFilterConnectionField
ImportError: cannot import name 'DjangoFilterConnectionField' from 'graphene_django.filter' (/usr/local/lib/python3.11/site-packages/graphene_django/filter/__init__.py)

During handling of the above exception, another exception occurred:

Traceback (most recent call last):
  File "/usr/local/lib/python3.11/site-packages/django/core/handlers/exception.py", line 55, in inner
    response = get_response(request)
               ^^^^^^^^^^^^^^^^^^^^^
  File "/usr/local/lib/python3.11/site-packages/django/core/handlers/base.py", line 197, in _get_response
    response = wrapped_callback(request, *callback_args, **callback_kwargs)
               ^^^^^^^^^^^^^^^^^^^^^^^^^^^^^^^^^^^^^^^^^^^^^^^^^^^^^^^^^^^^
  File "/usr/local/lib/python3.11/site-packages/django/views/decorators/csrf.py", line 56, in wrapper_view
    return view_func(*args, **kwargs)
           ^^^^^^^^^^^^^^^^^^^^^^^^^^
  File "/usr/local/lib/python3.11/site-packages/django/views/generic/base.py", line 97, in view
    self = cls(**initkwargs)
           ^^^^^^^^^^^^^^^^^
  File "/usr/local/lib/python3.11/site-packages/graphene_django/views.py", line 114, in __init__
    schema = graphene_settings.SCHEMA
             ^^^^^^^^^^^^^^^^^^^^^^^^
  File "/usr/local/lib/python3.11/site-packages/graphene_django/settings.py", line 127, in __getattr__
    val = perform_import(val, attr)
          ^^^^^^^^^^^^^^^^^^^^^^^^^
  File "/usr/local/lib/python3.11/site-packages/graphene_django/settings.py", line 66, in perform_import
    return import_from_string(val, setting_name)
           ^^^^^^^^^^^^^^^^^^^^^^^^^^^^^^^^^^^^^
  File "/usr/local/lib/python3.11/site-packages/graphene_django/settings.py", line 89, in import_from_string
    raise ImportError(msg)
ImportError: Could not import 'starwars.schema.schema' for Graphene setting 'SCHEMA'. ImportError: cannot import name 'DjangoFilterConnectionField' from 'graphene_django.filter' (/usr/local/lib/python3.11/site-packages/graphene_django/filter/__init__.py).
Internal Server Error: /graphql/
Traceback (most recent call last):
  File "/usr/local/lib/python3.11/site-packages/graphene_django/settings.py", line 80, in import_from_string
    module = importlib.import_module(module_path)
             ^^^^^^^^^^^^^^^^^^^^^^^^^^^^^^^^^^^^
  File "/usr/local/lib/python3.11/importlib/__init__.py", line 126, in import_module
    return _bootstrap._gcd_import(name[level:], package, level)
           ^^^^^^^^^^^^^^^^^^^^^^^^^^^^^^^^^^^^^^^^^^^^^^^^^^^^
  File "<frozen importlib._bootstrap>", line 1204, in _gcd_import
  File "<frozen importlib._bootstrap>", line 1176, in _find_and_load
  File "<frozen importlib._bootstrap>", line 1147, in _find_and_load_unlocked
  File "<frozen importlib._bootstrap>", line 690, in _load_unlocked
  File "<frozen importlib._bootstrap_external>", line 940, in exec_module
  File "<frozen importlib._bootstrap>", line 241, in _call_with_frames_removed
  File "/app/starwars/schema.py", line 4, in <module>
    from graphene_django.filter import DjangoFilterConnectionField
ImportError: cannot import name 'DjangoFilterConnectionField' from 'graphene_django.filter' (/usr/local/lib/python3.11/site-packages/graphene_django/filter/__init__.py)

During handling of the above exception, another exception occurred:

Traceback (most recent call last):
  File "/usr/local/lib/python3.11/site-packages/django/core/handlers/exception.py", line 55, in inner
    response = get_response(request)
               ^^^^^^^^^^^^^^^^^^^^^
  File "/usr/local/lib/python3.11/site-packages/django/core/handlers/base.py", line 197, in _get_response
    response = wrapped_callback(request, *callback_args, **callback_kwargs)
               ^^^^^^^^^^^^^^^^^^^^^^^^^^^^^^^^^^^^^^^^^^^^^^^^^^^^^^^^^^^^
  File "/usr/local/lib/python3.11/site-packages/django/views/decorators/csrf.py", line 56, in wrapper_view
    return view_func(*args, **kwargs)
           ^^^^^^^^^^^^^^^^^^^^^^^^^^
  File "/usr/local/lib/python3.11/site-packages/django/views/generic/base.py", line 97, in view
    self = cls(**initkwargs)
           ^^^^^^^^^^^^^^^^^
  File "/usr/local/lib/python3.11/site-packages/graphene_django/views.py", line 114, in __init__
    schema = graphene_settings.SCHEMA
             ^^^^^^^^^^^^^^^^^^^^^^^^
  File "/usr/local/lib/python3.11/site-packages/graphene_django/settings.py", line 127, in __getattr__
    val = perform_import(val, attr)
          ^^^^^^^^^^^^^^^^^^^^^^^^^
  File "/usr/local/lib/python3.11/site-packages/graphene_django/settings.py", line 66, in perform_import
    return import_from_string(val, setting_name)
           ^^^^^^^^^^^^^^^^^^^^^^^^^^^^^^^^^^^^^
  File "/usr/local/lib/python3.11/site-packages/graphene_django/settings.py", line 89, in import_from_string
    raise ImportError(msg)
ImportError: Could not import 'starwars.schema.schema' for Graphene setting 'SCHEMA'. ImportError: cannot import name 'DjangoFilterConnectionField' from 'graphene_django.filter' (/usr/local/lib/python3.11/site-packages/graphene_django/filter/__init__.py).
"POST /graphql/ HTTP/1.1" 500 122657
"POST /graphql/ HTTP/1.1" 500 122657
"POST /graphql/ HTTP/1.1" 500 122658
Not Found: /manifest.json
"GET /manifest.json HTTP/1.1" 404 2588
Internal Server Error: /graphql/
Traceback (most recent call last):
  File "/usr/local/lib/python3.11/site-packages/graphene_django/settings.py", line 80, in import_from_string
    module = importlib.import_module(module_path)
             ^^^^^^^^^^^^^^^^^^^^^^^^^^^^^^^^^^^^
  File "/usr/local/lib/python3.11/importlib/__init__.py", line 126, in import_module
    return _bootstrap._gcd_import(name[level:], package, level)
           ^^^^^^^^^^^^^^^^^^^^^^^^^^^^^^^^^^^^^^^^^^^^^^^^^^^^
  File "<frozen importlib._bootstrap>", line 1204, in _gcd_import
  File "<frozen importlib._bootstrap>", line 1176, in _find_and_load
  File "<frozen importlib._bootstrap>", line 1147, in _find_and_load_unlocked
  File "<frozen importlib._bootstrap>", line 690, in _load_unlocked
  File "<frozen importlib._bootstrap_external>", line 940, in exec_module
  File "<frozen importlib._bootstrap>", line 241, in _call_with_frames_removed
  File "/app/starwars/schema.py", line 4, in <module>
    from graphene_django.filter import DjangoFilterConnectionField
ImportError: cannot import name 'DjangoFilterConnectionField' from 'graphene_django.filter' (/usr/local/lib/python3.11/site-packages/graphene_django/filter/__init__.py)

During handling of the above exception, another exception occurred:

Traceback (most recent call last):
  File "/usr/local/lib/python3.11/site-packages/django/core/handlers/exception.py", line 55, in inner
    response = get_response(request)
               ^^^^^^^^^^^^^^^^^^^^^
  File "/usr/local/lib/python3.11/site-packages/django/core/handlers/base.py", line 197, in _get_response
    response = wrapped_callback(request, *callback_args, **callback_kwargs)
               ^^^^^^^^^^^^^^^^^^^^^^^^^^^^^^^^^^^^^^^^^^^^^^^^^^^^^^^^^^^^
  File "/usr/local/lib/python3.11/site-packages/django/views/decorators/csrf.py", line 56, in wrapper_view
    return view_func(*args, **kwargs)
           ^^^^^^^^^^^^^^^^^^^^^^^^^^
  File "/usr/local/lib/python3.11/site-packages/django/views/generic/base.py", line 97, in view
    self = cls(**initkwargs)
           ^^^^^^^^^^^^^^^^^
  File "/usr/local/lib/python3.11/site-packages/graphene_django/views.py", line 114, in __init__
    schema = graphene_settings.SCHEMA
             ^^^^^^^^^^^^^^^^^^^^^^^^
  File "/usr/local/lib/python3.11/site-packages/graphene_django/settings.py", line 127, in __getattr__
    val = perform_import(val, attr)
          ^^^^^^^^^^^^^^^^^^^^^^^^^
  File "/usr/local/lib/python3.11/site-packages/graphene_django/settings.py", line 66, in perform_import
    return import_from_string(val, setting_name)
           ^^^^^^^^^^^^^^^^^^^^^^^^^^^^^^^^^^^^^
  File "/usr/local/lib/python3.11/site-packages/graphene_django/settings.py", line 89, in import_from_string
    raise ImportError(msg)
ImportError: Could not import 'starwars.schema.schema' for Graphene setting 'SCHEMA'. ImportError: cannot import name 'DjangoFilterConnectionField' from 'graphene_django.filter' (/usr/local/lib/python3.11/site-packages/graphene_django/filter/__init__.py).
"POST /graphql/ HTTP/1.1" 500 122657
Internal Server Error: /graphql/
Traceback (most recent call last):
  File "/usr/local/lib/python3.11/site-packages/graphene_django/settings.py", line 80, in import_from_string
    module = importlib.import_module(module_path)
             ^^^^^^^^^^^^^^^^^^^^^^^^^^^^^^^^^^^^
  File "/usr/local/lib/python3.11/importlib/__init__.py", line 126, in import_module
    return _bootstrap._gcd_import(name[level:], package, level)
           ^^^^^^^^^^^^^^^^^^^^^^^^^^^^^^^^^^^^^^^^^^^^^^^^^^^^
  File "<frozen importlib._bootstrap>", line 1204, in _gcd_import
  File "<frozen importlib._bootstrap>", line 1176, in _find_and_load
  File "<frozen importlib._bootstrap>", line 1147, in _find_and_load_unlocked
  File "<frozen importlib._bootstrap>", line 690, in _load_unlocked
  File "<frozen importlib._bootstrap_external>", line 940, in exec_module
  File "<frozen importlib._bootstrap>", line 241, in _call_with_frames_removed
  File "/app/starwars/schema.py", line 4, in <module>
    from graphene_django.filter import DjangoFilterConnectionField
ImportError: cannot import name 'DjangoFilterConnectionField' from 'graphene_django.filter' (/usr/local/lib/python3.11/site-packages/graphene_django/filter/__init__.py)

During handling of the above exception, another exception occurred:

Traceback (most recent call last):
  File "/usr/local/lib/python3.11/site-packages/django/core/handlers/exception.py", line 55, in inner
    response = get_response(request)
               ^^^^^^^^^^^^^^^^^^^^^
  File "/usr/local/lib/python3.11/site-packages/django/core/handlers/base.py", line 197, in _get_response
    response = wrapped_callback(request, *callback_args, **callback_kwargs)
               ^^^^^^^^^^^^^^^^^^^^^^^^^^^^^^^^^^^^^^^^^^^^^^^^^^^^^^^^^^^^
  File "/usr/local/lib/python3.11/site-packages/django/views/decorators/csrf.py", line 56, in wrapper_view
    return view_func(*args, **kwargs)
           ^^^^^^^^^^^^^^^^^^^^^^^^^^
  File "/usr/local/lib/python3.11/site-packages/django/views/generic/base.py", line 97, in view
    self = cls(**initkwargs)
           ^^^^^^^^^^^^^^^^^
  File "/usr/local/lib/python3.11/site-packages/graphene_django/views.py", line 114, in __init__
    schema = graphene_settings.SCHEMA
             ^^^^^^^^^^^^^^^^^^^^^^^^
  File "/usr/local/lib/python3.11/site-packages/graphene_django/settings.py", line 127, in __getattr__
    val = perform_import(val, attr)
          ^^^^^^^^^^^^^^^^^^^^^^^^^
  File "/usr/local/lib/python3.11/site-packages/graphene_django/settings.py", line 66, in perform_import
    return import_from_string(val, setting_name)
           ^^^^^^^^^^^^^^^^^^^^^^^^^^^^^^^^^^^^^
  File "/usr/local/lib/python3.11/site-packages/graphene_django/settings.py", line 89, in import_from_string
    raise ImportError(msg)
ImportError: Could not import 'starwars.schema.schema' for Graphene setting 'SCHEMA'. ImportError: cannot import name 'DjangoFilterConnectionField' from 'graphene_django.filter' (/usr/local/lib/python3.11/site-packages/graphene_django/filter/__init__.py).
"POST /graphql/ HTTP/1.1" 500 122657
Internal Server Error: /graphql/
Traceback (most recent call last):
  File "/usr/local/lib/python3.11/site-packages/graphene_django/settings.py", line 80, in import_from_string
    module = importlib.import_module(module_path)
             ^^^^^^^^^^^^^^^^^^^^^^^^^^^^^^^^^^^^
  File "/usr/local/lib/python3.11/importlib/__init__.py", line 126, in import_module
    return _bootstrap._gcd_import(name[level:], package, level)
           ^^^^^^^^^^^^^^^^^^^^^^^^^^^^^^^^^^^^^^^^^^^^^^^^^^^^
  File "<frozen importlib._bootstrap>", line 1204, in _gcd_import
  File "<frozen importlib._bootstrap>", line 1176, in _find_and_load
  File "<frozen importlib._bootstrap>", line 1147, in _find_and_load_unlocked
  File "<frozen importlib._bootstrap>", line 690, in _load_unlocked
  File "<frozen importlib._bootstrap_external>", line 940, in exec_module
  File "<frozen importlib._bootstrap>", line 241, in _call_with_frames_removed
  File "/app/starwars/schema.py", line 4, in <module>
    from graphene_django.filter import DjangoFilterConnectionField
ImportError: cannot import name 'DjangoFilterConnectionField' from 'graphene_django.filter' (/usr/local/lib/python3.11/site-packages/graphene_django/filter/__init__.py)

During handling of the above exception, another exception occurred:

Traceback (most recent call last):
  File "/usr/local/lib/python3.11/site-packages/django/core/handlers/exception.py", line 55, in inner
    response = get_response(request)
               ^^^^^^^^^^^^^^^^^^^^^
  File "/usr/local/lib/python3.11/site-packages/django/core/handlers/base.py", line 197, in _get_response
    response = wrapped_callback(request, *callback_args, **callback_kwargs)
               ^^^^^^^^^^^^^^^^^^^^^^^^^^^^^^^^^^^^^^^^^^^^^^^^^^^^^^^^^^^^
  File "/usr/local/lib/python3.11/site-packages/django/views/decorators/csrf.py", line 56, in wrapper_view
    return view_func(*args, **kwargs)
           ^^^^^^^^^^^^^^^^^^^^^^^^^^
  File "/usr/local/lib/python3.11/site-packages/django/views/generic/base.py", line 97, in view
    self = cls(**initkwargs)
           ^^^^^^^^^^^^^^^^^
  File "/usr/local/lib/python3.11/site-packages/graphene_django/views.py", line 114, in __init__
    schema = graphene_settings.SCHEMA
             ^^^^^^^^^^^^^^^^^^^^^^^^
  File "/usr/local/lib/python3.11/site-packages/graphene_django/settings.py", line 127, in __getattr__
    val = perform_import(val, attr)
          ^^^^^^^^^^^^^^^^^^^^^^^^^
  File "/usr/local/lib/python3.11/site-packages/graphene_django/settings.py", line 66, in perform_import
    return import_from_string(val, setting_name)
           ^^^^^^^^^^^^^^^^^^^^^^^^^^^^^^^^^^^^^
  File "/usr/local/lib/python3.11/site-packages/graphene_django/settings.py", line 89, in import_from_string
    raise ImportError(msg)
ImportError: Could not import 'starwars.schema.schema' for Graphene setting 'SCHEMA'. ImportError: cannot import name 'DjangoFilterConnectionField' from 'graphene_django.filter' (/usr/local/lib/python3.11/site-packages/graphene_django/filter/__init__.py).
"POST /graphql/ HTTP/1.1" 500 122658
Watching for file changes with StatReloader
Not Found: /manifest.json
"GET /manifest.json HTTP/1.1" 404 2588
Internal Server Error: /graphql/
Traceback (most recent call last):
  File "/usr/local/lib/python3.11/site-packages/graphene_django/settings.py", line 80, in import_from_string
    module = importlib.import_module(module_path)
             ^^^^^^^^^^^^^^^^^^^^^^^^^^^^^^^^^^^^
  File "/usr/local/lib/python3.11/importlib/__init__.py", line 126, in import_module
    return _bootstrap._gcd_import(name[level:], package, level)
           ^^^^^^^^^^^^^^^^^^^^^^^^^^^^^^^^^^^^^^^^^^^^^^^^^^^^
  File "<frozen importlib._bootstrap>", line 1204, in _gcd_import
  File "<frozen importlib._bootstrap>", line 1176, in _find_and_load
  File "<frozen importlib._bootstrap>", line 1147, in _find_and_load_unlocked
  File "<frozen importlib._bootstrap>", line 690, in _load_unlocked
  File "<frozen importlib._bootstrap_external>", line 940, in exec_module
  File "<frozen importlib._bootstrap>", line 241, in _call_with_frames_removed
  File "/app/starwars/schema.py", line 4, in <module>
    from graphene_django.filter import DjangoFilterConnectionField
ImportError: cannot import name 'DjangoFilterConnectionField' from 'graphene_django.filter' (/usr/local/lib/python3.11/site-packages/graphene_django/filter/__init__.py)

During handling of the above exception, another exception occurred:

Traceback (most recent call last):
  File "/usr/local/lib/python3.11/site-packages/django/core/handlers/exception.py", line 55, in inner
    response = get_response(request)
               ^^^^^^^^^^^^^^^^^^^^^
  File "/usr/local/lib/python3.11/site-packages/django/core/handlers/base.py", line 197, in _get_response
    response = wrapped_callback(request, *callback_args, **callback_kwargs)
               ^^^^^^^^^^^^^^^^^^^^^^^^^^^^^^^^^^^^^^^^^^^^^^^^^^^^^^^^^^^^
  File "/usr/local/lib/python3.11/site-packages/django/views/decorators/csrf.py", line 56, in wrapper_view
    return view_func(*args, **kwargs)
           ^^^^^^^^^^^^^^^^^^^^^^^^^^
  File "/usr/local/lib/python3.11/site-packages/django/views/generic/base.py", line 97, in view
    self = cls(**initkwargs)
           ^^^^^^^^^^^^^^^^^
  File "/usr/local/lib/python3.11/site-packages/graphene_django/views.py", line 114, in __init__
    schema = graphene_settings.SCHEMA
             ^^^^^^^^^^^^^^^^^^^^^^^^
  File "/usr/local/lib/python3.11/site-packages/graphene_django/settings.py", line 127, in __getattr__
    val = perform_import(val, attr)
          ^^^^^^^^^^^^^^^^^^^^^^^^^
  File "/usr/local/lib/python3.11/site-packages/graphene_django/settings.py", line 66, in perform_import
    return import_from_string(val, setting_name)
           ^^^^^^^^^^^^^^^^^^^^^^^^^^^^^^^^^^^^^
  File "/usr/local/lib/python3.11/site-packages/graphene_django/settings.py", line 89, in import_from_string
    raise ImportError(msg)
ImportError: Could not import 'starwars.schema.schema' for Graphene setting 'SCHEMA'. ImportError: cannot import name 'DjangoFilterConnectionField' from 'graphene_django.filter' (/usr/local/lib/python3.11/site-packages/graphene_django/filter/__init__.py).
Internal Server Error: /graphql/
Traceback (most recent call last):
  File "/usr/local/lib/python3.11/site-packages/graphene_django/settings.py", line 80, in import_from_string
    module = importlib.import_module(module_path)
             ^^^^^^^^^^^^^^^^^^^^^^^^^^^^^^^^^^^^
  File "/usr/local/lib/python3.11/importlib/__init__.py", line 126, in import_module
    return _bootstrap._gcd_import(name[level:], package, level)
           ^^^^^^^^^^^^^^^^^^^^^^^^^^^^^^^^^^^^^^^^^^^^^^^^^^^^
  File "<frozen importlib._bootstrap>", line 1204, in _gcd_import
  File "<frozen importlib._bootstrap>", line 1176, in _find_and_load
  File "<frozen importlib._bootstrap>", line 1147, in _find_and_load_unlocked
  File "<frozen importlib._bootstrap>", line 690, in _load_unlocked
  File "<frozen importlib._bootstrap_external>", line 940, in exec_module
  File "<frozen importlib._bootstrap>", line 241, in _call_with_frames_removed
  File "/app/starwars/schema.py", line 4, in <module>
    from graphene_django.filter import DjangoFilterConnectionField
ImportError: cannot import name 'DjangoFilterConnectionField' from 'graphene_django.filter' (/usr/local/lib/python3.11/site-packages/graphene_django/filter/__init__.py)

During handling of the above exception, another exception occurred:

Traceback (most recent call last):
  File "/usr/local/lib/python3.11/site-packages/django/core/handlers/exception.py", line 55, in inner
    response = get_response(request)
               ^^^^^^^^^^^^^^^^^^^^^
  File "/usr/local/lib/python3.11/site-packages/django/core/handlers/base.py", line 197, in _get_response
    response = wrapped_callback(request, *callback_args, **callback_kwargs)
               ^^^^^^^^^^^^^^^^^^^^^^^^^^^^^^^^^^^^^^^^^^^^^^^^^^^^^^^^^^^^
  File "/usr/local/lib/python3.11/site-packages/django/views/decorators/csrf.py", line 56, in wrapper_view
    return view_func(*args, **kwargs)
           ^^^^^^^^^^^^^^^^^^^^^^^^^^
  File "/usr/local/lib/python3.11/site-packages/django/views/generic/base.py", line 97, in view
    self = cls(**initkwargs)
           ^^^^^^^^^^^^^^^^^
  File "/usr/local/lib/python3.11/site-packages/graphene_django/views.py", line 114, in __init__
    schema = graphene_settings.SCHEMA
             ^^^^^^^^^^^^^^^^^^^^^^^^
  File "/usr/local/lib/python3.11/site-packages/graphene_django/settings.py", line 127, in __getattr__
    val = perform_import(val, attr)
          ^^^^^^^^^^^^^^^^^^^^^^^^^
  File "/usr/local/lib/python3.11/site-packages/graphene_django/settings.py", line 66, in perform_import
    return import_from_string(val, setting_name)
           ^^^^^^^^^^^^^^^^^^^^^^^^^^^^^^^^^^^^^
  File "/usr/local/lib/python3.11/site-packages/graphene_django/settings.py", line 89, in import_from_string
    raise ImportError(msg)
ImportError: Could not import 'starwars.schema.schema' for Graphene setting 'SCHEMA'. ImportError: cannot import name 'DjangoFilterConnectionField' from 'graphene_django.filter' (/usr/local/lib/python3.11/site-packages/graphene_django/filter/__init__.py).
Internal Server Error: /graphql/
Traceback (most recent call last):
  File "/usr/local/lib/python3.11/site-packages/graphene_django/settings.py", line 80, in import_from_string
    module = importlib.import_module(module_path)
             ^^^^^^^^^^^^^^^^^^^^^^^^^^^^^^^^^^^^
  File "/usr/local/lib/python3.11/importlib/__init__.py", line 126, in import_module
    return _bootstrap._gcd_import(name[level:], package, level)
           ^^^^^^^^^^^^^^^^^^^^^^^^^^^^^^^^^^^^^^^^^^^^^^^^^^^^
  File "<frozen importlib._bootstrap>", line 1204, in _gcd_import
  File "<frozen importlib._bootstrap>", line 1176, in _find_and_load
  File "<frozen importlib._bootstrap>", line 1147, in _find_and_load_unlocked
  File "<frozen importlib._bootstrap>", line 690, in _load_unlocked
  File "<frozen importlib._bootstrap_external>", line 940, in exec_module
  File "<frozen importlib._bootstrap>", line 241, in _call_with_frames_removed
  File "/app/starwars/schema.py", line 4, in <module>
    from graphene_django.filter import DjangoFilterConnectionField
ImportError: cannot import name 'DjangoFilterConnectionField' from 'graphene_django.filter' (/usr/local/lib/python3.11/site-packages/graphene_django/filter/__init__.py)

During handling of the above exception, another exception occurred:

Traceback (most recent call last):
  File "/usr/local/lib/python3.11/site-packages/django/core/handlers/exception.py", line 55, in inner
    response = get_response(request)
               ^^^^^^^^^^^^^^^^^^^^^
  File "/usr/local/lib/python3.11/site-packages/django/core/handlers/base.py", line 197, in _get_response
    response = wrapped_callback(request, *callback_args, **callback_kwargs)
               ^^^^^^^^^^^^^^^^^^^^^^^^^^^^^^^^^^^^^^^^^^^^^^^^^^^^^^^^^^^^
  File "/usr/local/lib/python3.11/site-packages/django/views/decorators/csrf.py", line 56, in wrapper_view
    return view_func(*args, **kwargs)
           ^^^^^^^^^^^^^^^^^^^^^^^^^^
  File "/usr/local/lib/python3.11/site-packages/django/views/generic/base.py", line 97, in view
    self = cls(**initkwargs)
           ^^^^^^^^^^^^^^^^^
  File "/usr/local/lib/python3.11/site-packages/graphene_django/views.py", line 114, in __init__
    schema = graphene_settings.SCHEMA
             ^^^^^^^^^^^^^^^^^^^^^^^^
  File "/usr/local/lib/python3.11/site-packages/graphene_django/settings.py", line 127, in __getattr__
    val = perform_import(val, attr)
          ^^^^^^^^^^^^^^^^^^^^^^^^^
  File "/usr/local/lib/python3.11/site-packages/graphene_django/settings.py", line 66, in perform_import
    return import_from_string(val, setting_name)
           ^^^^^^^^^^^^^^^^^^^^^^^^^^^^^^^^^^^^^
  File "/usr/local/lib/python3.11/site-packages/graphene_django/settings.py", line 89, in import_from_string
    raise ImportError(msg)
ImportError: Could not import 'starwars.schema.schema' for Graphene setting 'SCHEMA'. ImportError: cannot import name 'DjangoFilterConnectionField' from 'graphene_django.filter' (/usr/local/lib/python3.11/site-packages/graphene_django/filter/__init__.py).
"POST /graphql/ HTTP/1.1" 500 122657
"POST /graphql/ HTTP/1.1" 500 122657
"POST /graphql/ HTTP/1.1" 500 122658
Internal Server Error: /graphql/
Traceback (most recent call last):
  File "/usr/local/lib/python3.11/site-packages/graphene_django/settings.py", line 80, in import_from_string
    module = importlib.import_module(module_path)
             ^^^^^^^^^^^^^^^^^^^^^^^^^^^^^^^^^^^^
  File "/usr/local/lib/python3.11/importlib/__init__.py", line 126, in import_module
    return _bootstrap._gcd_import(name[level:], package, level)
           ^^^^^^^^^^^^^^^^^^^^^^^^^^^^^^^^^^^^^^^^^^^^^^^^^^^^
  File "<frozen importlib._bootstrap>", line 1204, in _gcd_import
  File "<frozen importlib._bootstrap>", line 1176, in _find_and_load
  File "<frozen importlib._bootstrap>", line 1147, in _find_and_load_unlocked
  File "<frozen importlib._bootstrap>", line 690, in _load_unlocked
  File "<frozen importlib._bootstrap_external>", line 940, in exec_module
  File "<frozen importlib._bootstrap>", line 241, in _call_with_frames_removed
  File "/app/starwars/schema.py", line 4, in <module>
    from graphene_django.filter import DjangoFilterConnectionField
ImportError: cannot import name 'DjangoFilterConnectionField' from 'graphene_django.filter' (/usr/local/lib/python3.11/site-packages/graphene_django/filter/__init__.py)

During handling of the above exception, another exception occurred:

Traceback (most recent call last):
  File "/usr/local/lib/python3.11/site-packages/django/core/handlers/exception.py", line 55, in inner
    response = get_response(request)
               ^^^^^^^^^^^^^^^^^^^^^
  File "/usr/local/lib/python3.11/site-packages/django/core/handlers/base.py", line 197, in _get_response
    response = wrapped_callback(request, *callback_args, **callback_kwargs)
               ^^^^^^^^^^^^^^^^^^^^^^^^^^^^^^^^^^^^^^^^^^^^^^^^^^^^^^^^^^^^
  File "/usr/local/lib/python3.11/site-packages/django/views/decorators/csrf.py", line 56, in wrapper_view
    return view_func(*args, **kwargs)
           ^^^^^^^^^^^^^^^^^^^^^^^^^^
  File "/usr/local/lib/python3.11/site-packages/django/views/generic/base.py", line 97, in view
    self = cls(**initkwargs)
           ^^^^^^^^^^^^^^^^^
  File "/usr/local/lib/python3.11/site-packages/graphene_django/views.py", line 114, in __init__
    schema = graphene_settings.SCHEMA
             ^^^^^^^^^^^^^^^^^^^^^^^^
  File "/usr/local/lib/python3.11/site-packages/graphene_django/settings.py", line 127, in __getattr__
    val = perform_import(val, attr)
          ^^^^^^^^^^^^^^^^^^^^^^^^^
  File "/usr/local/lib/python3.11/site-packages/graphene_django/settings.py", line 66, in perform_import
    return import_from_string(val, setting_name)
           ^^^^^^^^^^^^^^^^^^^^^^^^^^^^^^^^^^^^^
  File "/usr/local/lib/python3.11/site-packages/graphene_django/settings.py", line 89, in import_from_string
    raise ImportError(msg)
ImportError: Could not import 'starwars.schema.schema' for Graphene setting 'SCHEMA'. ImportError: cannot import name 'DjangoFilterConnectionField' from 'graphene_django.filter' (/usr/local/lib/python3.11/site-packages/graphene_django/filter/__init__.py).
"POST /graphql/ HTTP/1.1" 500 122657
Internal Server Error: /graphql/
Traceback (most recent call last):
  File "/usr/local/lib/python3.11/site-packages/graphene_django/settings.py", line 80, in import_from_string
    module = importlib.import_module(module_path)
             ^^^^^^^^^^^^^^^^^^^^^^^^^^^^^^^^^^^^
  File "/usr/local/lib/python3.11/importlib/__init__.py", line 126, in import_module
    return _bootstrap._gcd_import(name[level:], package, level)
           ^^^^^^^^^^^^^^^^^^^^^^^^^^^^^^^^^^^^^^^^^^^^^^^^^^^^
  File "<frozen importlib._bootstrap>", line 1204, in _gcd_import
  File "<frozen importlib._bootstrap>", line 1176, in _find_and_load
  File "<frozen importlib._bootstrap>", line 1147, in _find_and_load_unlocked
  File "<frozen importlib._bootstrap>", line 690, in _load_unlocked
  File "<frozen importlib._bootstrap_external>", line 940, in exec_module
  File "<frozen importlib._bootstrap>", line 241, in _call_with_frames_removed
  File "/app/starwars/schema.py", line 4, in <module>
    from graphene_django.filter import DjangoFilterConnectionField
ImportError: cannot import name 'DjangoFilterConnectionField' from 'graphene_django.filter' (/usr/local/lib/python3.11/site-packages/graphene_django/filter/__init__.py)

During handling of the above exception, another exception occurred:

Traceback (most recent call last):
  File "/usr/local/lib/python3.11/site-packages/django/core/handlers/exception.py", line 55, in inner
    response = get_response(request)
               ^^^^^^^^^^^^^^^^^^^^^
  File "/usr/local/lib/python3.11/site-packages/django/core/handlers/base.py", line 197, in _get_response
    response = wrapped_callback(request, *callback_args, **callback_kwargs)
               ^^^^^^^^^^^^^^^^^^^^^^^^^^^^^^^^^^^^^^^^^^^^^^^^^^^^^^^^^^^^
  File "/usr/local/lib/python3.11/site-packages/django/views/decorators/csrf.py", line 56, in wrapper_view
    return view_func(*args, **kwargs)
           ^^^^^^^^^^^^^^^^^^^^^^^^^^
  File "/usr/local/lib/python3.11/site-packages/django/views/generic/base.py", line 97, in view
    self = cls(**initkwargs)
           ^^^^^^^^^^^^^^^^^
  File "/usr/local/lib/python3.11/site-packages/graphene_django/views.py", line 114, in __init__
    schema = graphene_settings.SCHEMA
             ^^^^^^^^^^^^^^^^^^^^^^^^
  File "/usr/local/lib/python3.11/site-packages/graphene_django/settings.py", line 127, in __getattr__
    val = perform_import(val, attr)
          ^^^^^^^^^^^^^^^^^^^^^^^^^
  File "/usr/local/lib/python3.11/site-packages/graphene_django/settings.py", line 66, in perform_import
    return import_from_string(val, setting_name)
           ^^^^^^^^^^^^^^^^^^^^^^^^^^^^^^^^^^^^^
  File "/usr/local/lib/python3.11/site-packages/graphene_django/settings.py", line 89, in import_from_string
    raise ImportError(msg)
ImportError: Could not import 'starwars.schema.schema' for Graphene setting 'SCHEMA'. ImportError: cannot import name 'DjangoFilterConnectionField' from 'graphene_django.filter' (/usr/local/lib/python3.11/site-packages/graphene_django/filter/__init__.py).
"POST /graphql/ HTTP/1.1" 500 122657
Internal Server Error: /graphql/
Traceback (most recent call last):
  File "/usr/local/lib/python3.11/site-packages/graphene_django/settings.py", line 80, in import_from_string
    module = importlib.import_module(module_path)
             ^^^^^^^^^^^^^^^^^^^^^^^^^^^^^^^^^^^^
  File "/usr/local/lib/python3.11/importlib/__init__.py", line 126, in import_module
    return _bootstrap._gcd_import(name[level:], package, level)
           ^^^^^^^^^^^^^^^^^^^^^^^^^^^^^^^^^^^^^^^^^^^^^^^^^^^^
  File "<frozen importlib._bootstrap>", line 1204, in _gcd_import
  File "<frozen importlib._bootstrap>", line 1176, in _find_and_load
  File "<frozen importlib._bootstrap>", line 1147, in _find_and_load_unlocked
  File "<frozen importlib._bootstrap>", line 690, in _load_unlocked
  File "<frozen importlib._bootstrap_external>", line 940, in exec_module
  File "<frozen importlib._bootstrap>", line 241, in _call_with_frames_removed
  File "/app/starwars/schema.py", line 4, in <module>
    from graphene_django.filter import DjangoFilterConnectionField
ImportError: cannot import name 'DjangoFilterConnectionField' from 'graphene_django.filter' (/usr/local/lib/python3.11/site-packages/graphene_django/filter/__init__.py)

During handling of the above exception, another exception occurred:

Traceback (most recent call last):
  File "/usr/local/lib/python3.11/site-packages/django/core/handlers/exception.py", line 55, in inner
    response = get_response(request)
               ^^^^^^^^^^^^^^^^^^^^^
  File "/usr/local/lib/python3.11/site-packages/django/core/handlers/base.py", line 197, in _get_response
    response = wrapped_callback(request, *callback_args, **callback_kwargs)
               ^^^^^^^^^^^^^^^^^^^^^^^^^^^^^^^^^^^^^^^^^^^^^^^^^^^^^^^^^^^^
  File "/usr/local/lib/python3.11/site-packages/django/views/decorators/csrf.py", line 56, in wrapper_view
    return view_func(*args, **kwargs)
           ^^^^^^^^^^^^^^^^^^^^^^^^^^
  File "/usr/local/lib/python3.11/site-packages/django/views/generic/base.py", line 97, in view
    self = cls(**initkwargs)
           ^^^^^^^^^^^^^^^^^
  File "/usr/local/lib/python3.11/site-packages/graphene_django/views.py", line 114, in __init__
    schema = graphene_settings.SCHEMA
             ^^^^^^^^^^^^^^^^^^^^^^^^
  File "/usr/local/lib/python3.11/site-packages/graphene_django/settings.py", line 127, in __getattr__
    val = perform_import(val, attr)
          ^^^^^^^^^^^^^^^^^^^^^^^^^
  File "/usr/local/lib/python3.11/site-packages/graphene_django/settings.py", line 66, in perform_import
    return import_from_string(val, setting_name)
           ^^^^^^^^^^^^^^^^^^^^^^^^^^^^^^^^^^^^^
  File "/usr/local/lib/python3.11/site-packages/graphene_django/settings.py", line 89, in import_from_string
    raise ImportError(msg)
ImportError: Could not import 'starwars.schema.schema' for Graphene setting 'SCHEMA'. ImportError: cannot import name 'DjangoFilterConnectionField' from 'graphene_django.filter' (/usr/local/lib/python3.11/site-packages/graphene_django/filter/__init__.py).
"POST /graphql/ HTTP/1.1" 500 122658
Not Found: /
"GET / HTTP/1.1" 404 2533
Not Found: /favicon.ico
"GET /favicon.ico HTTP/1.1" 404 2584
"GET /admin HTTP/1.1" 301 0
"GET /admin/ HTTP/1.1" 302 0
"GET /admin/login/?next=/admin/ HTTP/1.1" 200 4181
"GET /static/admin/css/base.css HTTP/1.1" 200 21207
"GET /static/admin/css/dark_mode.css HTTP/1.1" 200 2929
"GET /static/admin/css/nav_sidebar.css HTTP/1.1" 200 2694
"GET /static/admin/css/login.css HTTP/1.1" 200 958
"GET /static/admin/js/nav_sidebar.js HTTP/1.1" 200 3063
"GET /static/admin/js/theme.js HTTP/1.1" 200 1943
"GET /static/admin/css/responsive.css HTTP/1.1" 200 18533
"GET /static/admin/js/nav_sidebar.js HTTP/1.1" 200 3063
"GET /static/admin/js/theme.js HTTP/1.1" 200 1943
Not Found: /
"GET / HTTP/1.1" 404 2533
Internal Server Error: /graphql/
Traceback (most recent call last):
  File "/usr/local/lib/python3.11/site-packages/graphene_django/settings.py", line 80, in import_from_string
    module = importlib.import_module(module_path)
             ^^^^^^^^^^^^^^^^^^^^^^^^^^^^^^^^^^^^
  File "/usr/local/lib/python3.11/importlib/__init__.py", line 126, in import_module
    return _bootstrap._gcd_import(name[level:], package, level)
           ^^^^^^^^^^^^^^^^^^^^^^^^^^^^^^^^^^^^^^^^^^^^^^^^^^^^
  File "<frozen importlib._bootstrap>", line 1204, in _gcd_import
  File "<frozen importlib._bootstrap>", line 1176, in _find_and_load
  File "<frozen importlib._bootstrap>", line 1147, in _find_and_load_unlocked
  File "<frozen importlib._bootstrap>", line 690, in _load_unlocked
  File "<frozen importlib._bootstrap_external>", line 940, in exec_module
  File "<frozen importlib._bootstrap>", line 241, in _call_with_frames_removed
  File "/app/starwars/schema.py", line 4, in <module>
    from graphene_django.filter import DjangoFilterConnectionField
ImportError: cannot import name 'DjangoFilterConnectionField' from 'graphene_django.filter' (/usr/local/lib/python3.11/site-packages/graphene_django/filter/__init__.py)

During handling of the above exception, another exception occurred:

Traceback (most recent call last):
  File "/usr/local/lib/python3.11/site-packages/django/core/handlers/exception.py", line 55, in inner
    response = get_response(request)
               ^^^^^^^^^^^^^^^^^^^^^
  File "/usr/local/lib/python3.11/site-packages/django/core/handlers/base.py", line 197, in _get_response
    response = wrapped_callback(request, *callback_args, **callback_kwargs)
               ^^^^^^^^^^^^^^^^^^^^^^^^^^^^^^^^^^^^^^^^^^^^^^^^^^^^^^^^^^^^
  File "/usr/local/lib/python3.11/site-packages/django/views/decorators/csrf.py", line 56, in wrapper_view
    return view_func(*args, **kwargs)
           ^^^^^^^^^^^^^^^^^^^^^^^^^^
  File "/usr/local/lib/python3.11/site-packages/django/views/generic/base.py", line 97, in view
    self = cls(**initkwargs)
           ^^^^^^^^^^^^^^^^^
  File "/usr/local/lib/python3.11/site-packages/graphene_django/views.py", line 114, in __init__
    schema = graphene_settings.SCHEMA
             ^^^^^^^^^^^^^^^^^^^^^^^^
  File "/usr/local/lib/python3.11/site-packages/graphene_django/settings.py", line 127, in __getattr__
    val = perform_import(val, attr)
          ^^^^^^^^^^^^^^^^^^^^^^^^^
  File "/usr/local/lib/python3.11/site-packages/graphene_django/settings.py", line 66, in perform_import
    return import_from_string(val, setting_name)
           ^^^^^^^^^^^^^^^^^^^^^^^^^^^^^^^^^^^^^
  File "/usr/local/lib/python3.11/site-packages/graphene_django/settings.py", line 89, in import_from_string
    raise ImportError(msg)
ImportError: Could not import 'starwars.schema.schema' for Graphene setting 'SCHEMA'. ImportError: cannot import name 'DjangoFilterConnectionField' from 'graphene_django.filter' (/usr/local/lib/python3.11/site-packages/graphene_django/filter/__init__.py).
"GET /graphql/ HTTP/1.1" 500 123403
Not Found: /api/starwars/
"GET /api/starwars/ HTTP/1.1" 404 2839
Not Found: /api/graphql/
"GET /api/graphql/ HTTP/1.1" 404 2587
Internal Server Error: /graphql/
Traceback (most recent call last):
  File "/usr/local/lib/python3.11/site-packages/graphene_django/settings.py", line 80, in import_from_string
    module = importlib.import_module(module_path)
             ^^^^^^^^^^^^^^^^^^^^^^^^^^^^^^^^^^^^
  File "/usr/local/lib/python3.11/importlib/__init__.py", line 126, in import_module
    return _bootstrap._gcd_import(name[level:], package, level)
           ^^^^^^^^^^^^^^^^^^^^^^^^^^^^^^^^^^^^^^^^^^^^^^^^^^^^
  File "<frozen importlib._bootstrap>", line 1204, in _gcd_import
  File "<frozen importlib._bootstrap>", line 1176, in _find_and_load
  File "<frozen importlib._bootstrap>", line 1147, in _find_and_load_unlocked
  File "<frozen importlib._bootstrap>", line 690, in _load_unlocked
  File "<frozen importlib._bootstrap_external>", line 940, in exec_module
  File "<frozen importlib._bootstrap>", line 241, in _call_with_frames_removed
  File "/app/starwars/schema.py", line 4, in <module>
    from graphene_django.filter import DjangoFilterConnectionField
ImportError: cannot import name 'DjangoFilterConnectionField' from 'graphene_django.filter' (/usr/local/lib/python3.11/site-packages/graphene_django/filter/__init__.py)

During handling of the above exception, another exception occurred:

Traceback (most recent call last):
  File "/usr/local/lib/python3.11/site-packages/django/core/handlers/exception.py", line 55, in inner
    response = get_response(request)
               ^^^^^^^^^^^^^^^^^^^^^
  File "/usr/local/lib/python3.11/site-packages/django/core/handlers/base.py", line 197, in _get_response
    response = wrapped_callback(request, *callback_args, **callback_kwargs)
               ^^^^^^^^^^^^^^^^^^^^^^^^^^^^^^^^^^^^^^^^^^^^^^^^^^^^^^^^^^^^
  File "/usr/local/lib/python3.11/site-packages/django/views/decorators/csrf.py", line 56, in wrapper_view
    return view_func(*args, **kwargs)
           ^^^^^^^^^^^^^^^^^^^^^^^^^^
  File "/usr/local/lib/python3.11/site-packages/django/views/generic/base.py", line 97, in view
    self = cls(**initkwargs)
           ^^^^^^^^^^^^^^^^^
  File "/usr/local/lib/python3.11/site-packages/graphene_django/views.py", line 114, in __init__
    schema = graphene_settings.SCHEMA
             ^^^^^^^^^^^^^^^^^^^^^^^^
  File "/usr/local/lib/python3.11/site-packages/graphene_django/settings.py", line 127, in __getattr__
    val = perform_import(val, attr)
          ^^^^^^^^^^^^^^^^^^^^^^^^^
  File "/usr/local/lib/python3.11/site-packages/graphene_django/settings.py", line 66, in perform_import
    return import_from_string(val, setting_name)
           ^^^^^^^^^^^^^^^^^^^^^^^^^^^^^^^^^^^^^
  File "/usr/local/lib/python3.11/site-packages/graphene_django/settings.py", line 89, in import_from_string
    raise ImportError(msg)
ImportError: Could not import 'starwars.schema.schema' for Graphene setting 'SCHEMA'. ImportError: cannot import name 'DjangoFilterConnectionField' from 'graphene_django.filter' (/usr/local/lib/python3.11/site-packages/graphene_django/filter/__init__.py).
"GET /graphql/ HTTP/1.1" 500 123403
Watching for file changes with StatReloader
Not Found: /manifest.json
"GET /manifest.json HTTP/1.1" 404 2588
Internal Server Error: /graphql/
Traceback (most recent call last):
  File "/usr/local/lib/python3.11/site-packages/graphene_django/settings.py", line 80, in import_from_string
    module = importlib.import_module(module_path)
             ^^^^^^^^^^^^^^^^^^^^^^^^^^^^^^^^^^^^
  File "/usr/local/lib/python3.11/importlib/__init__.py", line 126, in import_module
    return _bootstrap._gcd_import(name[level:], package, level)
           ^^^^^^^^^^^^^^^^^^^^^^^^^^^^^^^^^^^^^^^^^^^^^^^^^^^^
  File "<frozen importlib._bootstrap>", line 1204, in _gcd_import
  File "<frozen importlib._bootstrap>", line 1176, in _find_and_load
  File "<frozen importlib._bootstrap>", line 1147, in _find_and_load_unlocked
  File "<frozen importlib._bootstrap>", line 690, in _load_unlocked
  File "<frozen importlib._bootstrap_external>", line 940, in exec_module
  File "<frozen importlib._bootstrap>", line 241, in _call_with_frames_removed
  File "/app/starwars/schema.py", line 4, in <module>
    from graphene_django.filter import DjangoFilterConnectionField
ImportError: cannot import name 'DjangoFilterConnectionField' from 'graphene_django.filter' (/usr/local/lib/python3.11/site-packages/graphene_django/filter/__init__.py)

During handling of the above exception, another exception occurred:

Traceback (most recent call last):
  File "/usr/local/lib/python3.11/site-packages/django/core/handlers/exception.py", line 55, in inner
    response = get_response(request)
               ^^^^^^^^^^^^^^^^^^^^^
  File "/usr/local/lib/python3.11/site-packages/django/core/handlers/base.py", line 197, in _get_response
    response = wrapped_callback(request, *callback_args, **callback_kwargs)
               ^^^^^^^^^^^^^^^^^^^^^^^^^^^^^^^^^^^^^^^^^^^^^^^^^^^^^^^^^^^^
  File "/usr/local/lib/python3.11/site-packages/django/views/decorators/csrf.py", line 56, in wrapper_view
    return view_func(*args, **kwargs)
           ^^^^^^^^^^^^^^^^^^^^^^^^^^
  File "/usr/local/lib/python3.11/site-packages/django/views/generic/base.py", line 97, in view
    self = cls(**initkwargs)
           ^^^^^^^^^^^^^^^^^
  File "/usr/local/lib/python3.11/site-packages/graphene_django/views.py", line 114, in __init__
    schema = graphene_settings.SCHEMA
             ^^^^^^^^^^^^^^^^^^^^^^^^
  File "/usr/local/lib/python3.11/site-packages/graphene_django/settings.py", line 127, in __getattr__
    val = perform_import(val, attr)
          ^^^^^^^^^^^^^^^^^^^^^^^^^
  File "/usr/local/lib/python3.11/site-packages/graphene_django/settings.py", line 66, in perform_import
    return import_from_string(val, setting_name)
           ^^^^^^^^^^^^^^^^^^^^^^^^^^^^^^^^^^^^^
  File "/usr/local/lib/python3.11/site-packages/graphene_django/settings.py", line 89, in import_from_string
    raise ImportError(msg)
ImportError: Could not import 'starwars.schema.schema' for Graphene setting 'SCHEMA'. ImportError: cannot import name 'DjangoFilterConnectionField' from 'graphene_django.filter' (/usr/local/lib/python3.11/site-packages/graphene_django/filter/__init__.py).
Internal Server Error: /graphql/
Traceback (most recent call last):
  File "/usr/local/lib/python3.11/site-packages/graphene_django/settings.py", line 80, in import_from_string
    module = importlib.import_module(module_path)
             ^^^^^^^^^^^^^^^^^^^^^^^^^^^^^^^^^^^^
  File "/usr/local/lib/python3.11/importlib/__init__.py", line 126, in import_module
    return _bootstrap._gcd_import(name[level:], package, level)
           ^^^^^^^^^^^^^^^^^^^^^^^^^^^^^^^^^^^^^^^^^^^^^^^^^^^^
  File "<frozen importlib._bootstrap>", line 1204, in _gcd_import
  File "<frozen importlib._bootstrap>", line 1176, in _find_and_load
  File "<frozen importlib._bootstrap>", line 1147, in _find_and_load_unlocked
  File "<frozen importlib._bootstrap>", line 690, in _load_unlocked
  File "<frozen importlib._bootstrap_external>", line 940, in exec_module
  File "<frozen importlib._bootstrap>", line 241, in _call_with_frames_removed
  File "/app/starwars/schema.py", line 4, in <module>
    from graphene_django.filter import DjangoFilterConnectionField
ImportError: cannot import name 'DjangoFilterConnectionField' from 'graphene_django.filter' (/usr/local/lib/python3.11/site-packages/graphene_django/filter/__init__.py)

During handling of the above exception, another exception occurred:

Traceback (most recent call last):
  File "/usr/local/lib/python3.11/site-packages/django/core/handlers/exception.py", line 55, in inner
    response = get_response(request)
               ^^^^^^^^^^^^^^^^^^^^^
  File "/usr/local/lib/python3.11/site-packages/django/core/handlers/base.py", line 197, in _get_response
    response = wrapped_callback(request, *callback_args, **callback_kwargs)
               ^^^^^^^^^^^^^^^^^^^^^^^^^^^^^^^^^^^^^^^^^^^^^^^^^^^^^^^^^^^^
  File "/usr/local/lib/python3.11/site-packages/django/views/decorators/csrf.py", line 56, in wrapper_view
    return view_func(*args, **kwargs)
           ^^^^^^^^^^^^^^^^^^^^^^^^^^
  File "/usr/local/lib/python3.11/site-packages/django/views/generic/base.py", line 97, in view
    self = cls(**initkwargs)
           ^^^^^^^^^^^^^^^^^
  File "/usr/local/lib/python3.11/site-packages/graphene_django/views.py", line 114, in __init__
    schema = graphene_settings.SCHEMA
             ^^^^^^^^^^^^^^^^^^^^^^^^
  File "/usr/local/lib/python3.11/site-packages/graphene_django/settings.py", line 127, in __getattr__
    val = perform_import(val, attr)
          ^^^^^^^^^^^^^^^^^^^^^^^^^
  File "/usr/local/lib/python3.11/site-packages/graphene_django/settings.py", line 66, in perform_import
    return import_from_string(val, setting_name)
           ^^^^^^^^^^^^^^^^^^^^^^^^^^^^^^^^^^^^^
  File "/usr/local/lib/python3.11/site-packages/graphene_django/settings.py", line 89, in import_from_string
    raise ImportError(msg)
ImportError: Could not import 'starwars.schema.schema' for Graphene setting 'SCHEMA'. ImportError: cannot import name 'DjangoFilterConnectionField' from 'graphene_django.filter' (/usr/local/lib/python3.11/site-packages/graphene_django/filter/__init__.py).
Internal Server Error: /graphql/
Traceback (most recent call last):
  File "/usr/local/lib/python3.11/site-packages/graphene_django/settings.py", line 80, in import_from_string
    module = importlib.import_module(module_path)
             ^^^^^^^^^^^^^^^^^^^^^^^^^^^^^^^^^^^^
  File "/usr/local/lib/python3.11/importlib/__init__.py", line 126, in import_module
    return _bootstrap._gcd_import(name[level:], package, level)
           ^^^^^^^^^^^^^^^^^^^^^^^^^^^^^^^^^^^^^^^^^^^^^^^^^^^^
  File "<frozen importlib._bootstrap>", line 1204, in _gcd_import
  File "<frozen importlib._bootstrap>", line 1176, in _find_and_load
  File "<frozen importlib._bootstrap>", line 1147, in _find_and_load_unlocked
  File "<frozen importlib._bootstrap>", line 690, in _load_unlocked
  File "<frozen importlib._bootstrap_external>", line 940, in exec_module
  File "<frozen importlib._bootstrap>", line 241, in _call_with_frames_removed
  File "/app/starwars/schema.py", line 4, in <module>
    from graphene_django.filter import DjangoFilterConnectionField
ImportError: cannot import name 'DjangoFilterConnectionField' from 'graphene_django.filter' (/usr/local/lib/python3.11/site-packages/graphene_django/filter/__init__.py)

During handling of the above exception, another exception occurred:

Traceback (most recent call last):
  File "/usr/local/lib/python3.11/site-packages/django/core/handlers/exception.py", line 55, in inner
    response = get_response(request)
               ^^^^^^^^^^^^^^^^^^^^^
  File "/usr/local/lib/python3.11/site-packages/django/core/handlers/base.py", line 197, in _get_response
    response = wrapped_callback(request, *callback_args, **callback_kwargs)
               ^^^^^^^^^^^^^^^^^^^^^^^^^^^^^^^^^^^^^^^^^^^^^^^^^^^^^^^^^^^^
  File "/usr/local/lib/python3.11/site-packages/django/views/decorators/csrf.py", line 56, in wrapper_view
    return view_func(*args, **kwargs)
           ^^^^^^^^^^^^^^^^^^^^^^^^^^
  File "/usr/local/lib/python3.11/site-packages/django/views/generic/base.py", line 97, in view
    self = cls(**initkwargs)
           ^^^^^^^^^^^^^^^^^
  File "/usr/local/lib/python3.11/site-packages/graphene_django/views.py", line 114, in __init__
    schema = graphene_settings.SCHEMA
             ^^^^^^^^^^^^^^^^^^^^^^^^
  File "/usr/local/lib/python3.11/site-packages/graphene_django/settings.py", line 127, in __getattr__
    val = perform_import(val, attr)
          ^^^^^^^^^^^^^^^^^^^^^^^^^
  File "/usr/local/lib/python3.11/site-packages/graphene_django/settings.py", line 66, in perform_import
    return import_from_string(val, setting_name)
           ^^^^^^^^^^^^^^^^^^^^^^^^^^^^^^^^^^^^^
  File "/usr/local/lib/python3.11/site-packages/graphene_django/settings.py", line 89, in import_from_string
    raise ImportError(msg)
ImportError: Could not import 'starwars.schema.schema' for Graphene setting 'SCHEMA'. ImportError: cannot import name 'DjangoFilterConnectionField' from 'graphene_django.filter' (/usr/local/lib/python3.11/site-packages/graphene_django/filter/__init__.py).
"POST /graphql/ HTTP/1.1" 500 122657
"POST /graphql/ HTTP/1.1" 500 122657
"POST /graphql/ HTTP/1.1" 500 122658
Watching for file changes with StatReloader
Not Found: /manifest.json
"GET /manifest.json HTTP/1.1" 404 2588
"POST /graphql/ HTTP/1.1" 200 259
"POST /graphql/ HTTP/1.1" 200 267
"POST /graphql/ HTTP/1.1" 200 265
"POST /graphql/ HTTP/1.1" 200 265
"POST /graphql/ HTTP/1.1" 200 259
"POST /graphql/ HTTP/1.1" 200 267
"POST /graphql/ HTTP/1.1" 200 185
"POST /graphql/ HTTP/1.1" 200 189
"POST /graphql/ HTTP/1.1" 200 188
Not Found: /manifest.json
"GET /manifest.json HTTP/1.1" 404 2588
"POST /graphql/ HTTP/1.1" 200 188
"POST /graphql/ HTTP/1.1" 200 185
"POST /graphql/ HTTP/1.1" 200 189
"POST /graphql/ HTTP/1.1" 200 185
Not Found: /manifest.json
"POST /graphql/ HTTP/1.1" 200 188
"GET /manifest.json HTTP/1.1" 404 2588
"POST /graphql/ HTTP/1.1" 200 188
"POST /graphql/ HTTP/1.1" 200 185
"POST /graphql/ HTTP/1.1" 200 189
Not Found: /manifest.json
"GET /manifest.json HTTP/1.1" 404 2588
"POST /graphql/ HTTP/1.1" 200 188
"POST /graphql/ HTTP/1.1" 200 185
"POST /graphql/ HTTP/1.1" 200 189
Not Found: /manifest.json
"GET /manifest.json HTTP/1.1" 404 2588
"POST /graphql/ HTTP/1.1" 200 188
"POST /graphql/ HTTP/1.1" 200 185
"POST /graphql/ HTTP/1.1" 200 189
"POST /graphql/ HTTP/1.1" 200 188
"POST /graphql/ HTTP/1.1" 200 185
"POST /graphql/ HTTP/1.1" 200 189
"POST /graphql/ HTTP/1.1" 200 1527
"POST /graphql/ HTTP/1.1" 200 7104
Not Found: /manifest.json
"GET /manifest.json HTTP/1.1" 404 2588
"POST /graphql/ HTTP/1.1" 200 943
"POST /graphql/ HTTP/1.1" 200 44595
"POST /graphql/ HTTP/1.1" 200 37138
"POST /graphql/ HTTP/1.1" 200 23370
"GET /graphql HTTP/1.1" 301 0
"GET /graphql/ HTTP/1.1" 200 2611
"GET /static/graphene_django/graphiql.js HTTP/1.1" 200 4037
"GET /static/graphene_django/graphiql.js HTTP/1.1" 200 4037
"POST /graphql/ HTTP/1.1" 200 54449
"POST /graphql/ HTTP/1.1" 200 507
"POST /graphql/ HTTP/1.1" 200 987
Not Found: /.well-known/appspecific/com.chrome.devtools.json
"GET /.well-known/appspecific/com.chrome.devtools.json HTTP/1.1" 404 2695
"POST /graphql/ HTTP/1.1" 200 166
